Traceback (most recent call last):
  File "C:/Users/Mason/Desktop/Python/Section 12/35_error.py", line 5, in <module>
    raise Exception('This is the error message.')
Exception: This is the error message.
